import { describe, it, expect, vi } from 'vitest'
import { render, screen } from '@testing-library/react'
import React from 'react'
import ErrorBoundary from '@/app/components/ErrorBoundary'

// Mock ErrorService
vi.mock('@/lib/monitoring/error-service', () => ({
  ErrorService: {
    logError: vi.fn(),
  }
}))

// Test component that throws an error
const ThrowError = ({ shouldThrow }: { shouldThrow: boolean }) => {
  if (shouldThrow) {
    throw new Error('Test error')
  }
  return <div>No error</div>
}

describe('ErrorBoundary', () => {
  it('renders children when there is no error', () => {
    render(
      <ErrorBoundary>
        <ThrowError shouldThrow={false} />
      </ErrorBoundary>
    )
    
    expect(screen.getByText('No error')).toBeInTheDocument()
  })

  it('renders error UI when there is an error', () => {
    // Suppress console.error for this test
    const consoleSpy = vi.spyOn(console, 'error').mockImplementation(() => {})
    
    render(
      <ErrorBoundary>
        <ThrowError shouldThrow={true} />
      </ErrorBoundary>
    )
    
    expect(screen.getByText('Something went wrong')).toBeInTheDocument()
    expect(screen.getByText('Try again')).toBeInTheDocument()
    expect(screen.getByText('Reload page')).toBeInTheDocument()
    
    consoleSpy.mockRestore()
  })

  it('renders custom fallback when provided', () => {
    const consoleSpy = vi.spyOn(console, 'error').mockImplementation(() => {})
    const fallback = <div>Custom error message</div>
    
    render(
      <ErrorBoundary fallback={fallback}>
        <ThrowError shouldThrow={true} />
      </ErrorBoundary>
    )
    
    expect(screen.getByText('Custom error message')).toBeInTheDocument()
    
    consoleSpy.mockRestore()
  })
})

